Workbook

Sheet Students Grade
A1: Student ID | B1: Name | C1: Math | D1: Science | E1: English | F1: Enrollment Date | G1: Total | H1: Average | I1: Grade | J1: Result | K1: Math & Science >80 | L1: Math >60 or English >80 | M1: Full Name | N1: Enrollment Year | O1: Days Enrolled | P1: High Performer
A2: 1001 | B2: Student 1 | C2: 61 | D2: 48 | E2: 76 | F2: 43101 | G2: =SUM(C2:E2) -> 185 | H2: =AVERAGE(C2:E2) -> 61.666667 | I2: =IF(H2>=80,"A",IF(H2>=60,"B",IF(H2>=40,"C","F"))) -> B | J2: =IF(AND(C2>=40,D2>=40,E2>=40),"Pass","Fail") -> Pass | K2: =IF(AND(C2>80,D2>80),"Yes","No") -> No | L2: =IF(OR(C2>60,E2>80),"Yes","No") -> Yes | M2: =B2&" ("&A2&")" -> Student 1 (1001) | N2: =YEAR(F2) -> 2018 | O2: =MAX(0,TODAY()-F2) -> 3222 | P2: =IF(H2>80,"Yes","No") -> No
A3: 1002 | B3: Student 2 | C3: 78 | D3: 76 | E3: 70 | F3: 43281 | G3: =SUM(C3:E3) -> 224 | H3: =AVERAGE(C3:E3) -> 74.666667 | I3: =IF(H3>=80,"A",IF(H3>=60,"B",IF(H3>=40,"C","F"))) -> B | J3: =IF(AND(C3>=40,D3>=40,E3>=40),"Pass","Fail") -> Pass | K3: =IF(AND(C3>80,D3>80),"Yes","No") -> No | L3: =IF(OR(C3>60,E3>80),"Yes","No") -> Yes | M3: =B3&" ("&A3&")" -> Student 2 (1002) | N3: =YEAR(F3) -> 2018 | O3: =MAX(0,TODAY()-F3) -> 3042 | P3: =IF(H3>80,"Yes","No") -> No
A4: 1003 | B4: Student 3 | C4: 97 | D4: 60 | E4: 51 | F4: 43461 | G4: =SUM(C4:E4) -> 208 | H4: =AVERAGE(C4:E4) -> 69.333333 | I4: =IF(H4>=80,"A",IF(H4>=60,"B",IF(H4>=40,"C","F"))) -> B | J4: =IF(AND(C4>=40,D4>=40,E4>=40),"Pass","Fail") -> Pass | K4: =IF(AND(C4>80,D4>80),"Yes","No") -> No | L4: =IF(OR(C4>60,E4>80),"Yes","No") -> Yes | M4: =B4&" ("&A4&")" -> Student 3 (1003) | N4: =YEAR(F4) -> 2018 | O4: =MAX(0,TODAY()-F4) -> 2862 | P4: =IF(H4>80,"Yes","No") -> No
A5: 1004 | B5: Student 4 | C5: 74 | D5: 55 | E5: 46 | F5: 43641 | G5: =SUM(C5:E5) -> 175 | H5: =AVERAGE(C5:E5) -> 58.333333 | I5: =IF(H5>=80,"A",IF(H5>=60,"B",IF(H5>=40,"C","F"))) -> C | J5: =IF(AND(C5>=40,D5>=40,E5>=40),"Pass","Fail") -> Pass | K5: =IF(AND(C5>80,D5>80),"Yes","No") -> No | L5: =IF(OR(C5>60,E5>80),"Yes","No") -> Yes | M5: =B5&" ("&A5&")" -> Student 4 (1004) | N5: =YEAR(F5) -> 2019 | O5: =MAX(0,TODAY()-F5) -> 2682 | P5: =IF(H5>80,"Yes","No") -> No
A6: 1005 | B6: Student 5 | C6: 68 | D6: 74 | E6: 84 | F6: 43821 | G6: =SUM(C6:E6) -> 226 | H6: =AVERAGE(C6:E6) -> 75.333333 | I6: =IF(H6>=80,"A",IF(H6>=60,"B",IF(H6>=40,"C","F"))) -> B | J6: =IF(AND(C6>=40,D6>=40,E6>=40),"Pass","Fail") -> Pass | K6: =IF(AND(C6>80,D6>80),"Yes","No") -> No | L6: =IF(OR(C6>60,E6>80),"Yes","No") -> Yes | M6: =B6&" ("&A6&")" -> Student 5 (1005) | N6: =YEAR(F6) -> 2019 | O6: =MAX(0,TODAY()-F6) -> 2502 | P6: =IF(H6>80,"Yes","No") -> No
A7: 1006 | B7: Student 6 | C7: 80 | D7: 70 | E7: 65 | F7: 44001 | G7: =SUM(C7:E7) -> 215 | H7: =AVERAGE(C7:E7) -> 71.666667 | I7: =IF(H7>=80,"A",IF(H7>=60,"B",IF(H7>=40,"C","F"))) -> B | J7: =IF(AND(C7>=40,D7>=40,E7>=40),"Pass","Fail") -> Pass | K7: =IF(AND(C7>80,D7>80),"Yes","No") -> No | L7: =IF(OR(C7>60,E7>80),"Yes","No") -> Yes | M7: =B7&" ("&A7&")" -> Student 6 (1006) | N7: =YEAR(F7) -> 2020 | O7: =MAX(0,TODAY()-F7) -> 2322 | P7: =IF(H7>80,"Yes","No") -> No
A8: 1007 | B8: Student 7 | C8: 75 | D8: 47 | E8: 78 | F8: 44181 | G8: =SUM(C8:E8) -> 200 | H8: =AVERAGE(C8:E8) -> 66.666667 | I8: =IF(H8>=80,"A",IF(H8>=60,"B",IF(H8>=40,"C","F"))) -> B | J8: =IF(AND(C8>=40,D8>=40,E8>=40),"Pass","Fail") -> Pass | K8: =IF(AND(C8>80,D8>80),"Yes","No") -> No | L8: =IF(OR(C8>60,E8>80),"Yes","No") -> Yes | M8: =B8&" ("&A8&")" -> Student 7 (1007) | N8: =YEAR(F8) -> 2020 | O8: =MAX(0,TODAY()-F8) -> 2142 | P8: =IF(H8>80,"Yes","No") -> No
A9: 1008 | B9: Student 8 | C9: 94 | D9: 67 | E9: 64 | F9: 44361 | G9: =SUM(C9:E9) -> 225 | H9: =AVERAGE(C9:E9) -> 75 | I9: =IF(H9>=80,"A",IF(H9>=60,"B",IF(H9>=40,"C","F"))) -> B | J9: =IF(AND(C9>=40,D9>=40,E9>=40),"Pass","Fail") -> Pass | K9: =IF(AND(C9>80,D9>80),"Yes","No") -> No | L9: =IF(OR(C9>60,E9>80),"Yes","No") -> Yes | M9: =B9&" ("&A9&")" -> Student 8 (1008) | N9: =YEAR(F9) -> 2021 | O9: =MAX(0,TODAY()-F9) -> 1962 | P9: =IF(H9>80,"Yes","No") -> No
A10: 1009 | B10: Student 9 | C10: 41 | D10: 75 | E10: 56 | F10: 44541 | G10: =SUM(C10:E10) -> 172 | H10: =AVERAGE(C10:E10) -> 57.333333 | I10: =IF(H10>=80,"A",IF(H10>=60,"B",IF(H10>=40,"C","F"))) -> C | J10: =IF(AND(C10>=40,D10>=40,E10>=40),"Pass","Fail") -> Pass | K10: =IF(AND(C10>80,D10>80),"Yes","No") -> No | L10: =IF(OR(C10>60,E10>80),"Yes","No") -> No | M10: =B10&" ("&A10&")" -> Student 9 (1009) | N10: =YEAR(F10) -> 2021 | O10: =MAX(0,TODAY()-F10) -> 1782 | P10: =IF(H10>80,"Yes","No") -> No
A11: 1010 | B11: Student 10 | C11: 98 | D11: 54 | E11: 58 | F11: 44721 | G11: =SUM(C11:E11) -> 210 | H11: =AVERAGE(C11:E11) -> 70 | I11: =IF(H11>=80,"A",IF(H11>=60,"B",IF(H11>=40,"C","F"))) -> B | J11: =IF(AND(C11>=40,D11>=40,E11>=40),"Pass","Fail") -> Pass | K11: =IF(AND(C11>80,D11>80),"Yes","No") -> No | L11: =IF(OR(C11>60,E11>80),"Yes","No") -> Yes | M11: =B11&" ("&A11&")" -> Student 10 (1010) | N11: =YEAR(F11) -> 2022 | O11: =MAX(0,TODAY()-F11) -> 1602 | P11: =IF(H11>80,"Yes","No") -> No
A12: 1011 | B12: Student 11 | C12: 73 | D12: 79 | E12: 53 | F12: 44901 | G12: =SUM(C12:E12) -> 205 | H12: =AVERAGE(C12:E12) -> 68.333333 | I12: =IF(H12>=80,"A",IF(H12>=60,"B",IF(H12>=40,"C","F"))) -> B | J12: =IF(AND(C12>=40,D12>=40,E12>=40),"Pass","Fail") -> Pass | K12: =IF(AND(C12>80,D12>80),"Yes","No") -> No | L12: =IF(OR(C12>60,E12>80),"Yes","No") -> Yes | M12: =B12&" ("&A12&")" -> Student 11 (1011) | N12: =YEAR(F12) -> 2022 | O12: =MAX(0,TODAY()-F12) -> 1422 | P12: =IF(H12>80,"Yes","No") -> No
A13: 1012 | B13: Student 12 | C13: 85 | D13: 89 | E13: 79 | F13: 45081 | G13: =SUM(C13:E13) -> 253 | H13: =AVERAGE(C13:E13) -> 84.333333 | I13: =IF(H13>=80,"A",IF(H13>=60,"B",IF(H13>=40,"C","F"))) -> A | J13: =IF(AND(C13>=40,D13>=40,E13>=40),"Pass","Fail") -> Pass | K13: =IF(AND(C13>80,D13>80),"Yes","No") -> Yes | L13: =IF(OR(C13>60,E13>80),"Yes","No") -> Yes | M13: =B13&" ("&A13&")" -> Student 12 (1012) | N13: =YEAR(F13) -> 2023 | O13: =MAX(0,TODAY()-F13) -> 1242 | P13: =IF(H13>80,"Yes","No") -> Yes
... A21: 1020 | B21: Student 20 | C21: 83 | D21: 92 | E21: 55 | F21: 46521 | G21: =SUM(C21:E21) -> 230 | H21: =AVERAGE(C21:E21) -> 76.666667 | I21: =IF(H21>=80,"A",IF(H21>=60,"B",IF(H21>=40,"C","F"))) -> B | J21: =IF(AND(C21>=40,D21>=40,E21>=40),"Pass","Fail") -> Pass | K21: =IF(AND(C21>80,D21>80),"Yes","No") -> Yes | L21: =IF(OR(C21>60,E21>80),"Yes","No") -> Yes | M21: =B21&" ("&A21&")" -> Student 20 (1020) | N21: =YEAR(F21) -> 2027 | O21: =MAX(0,TODAY()-F21) -> 0 | P21: =IF(H21>80,"Yes","No") -> No

Sheet Sales Data
A1: Sales ID | B1: Product | C1: Region | D1: Salesperson | E1: Amount | F1: Date | G1: Month | H1: Year | I1: Amount with 5% Bonus
A2: 2001 | B2: Keyboard | C2: South | D2: Person 1 | E2: 7048 | F2: 44927 | G2: =TEXT(F2,"mmm") -> Jan | H2: =YEAR(F2) -> 2023 | I2: =E2*(1+'Formula Practice'!$B$3) -> 7400.4
A3: 2002 | B3: Printer | C3: West | D3: Person 2 | E3: 17428 | F3: 44942 | G3: =TEXT(F3,"mmm") -> Jan | H3: =YEAR(F3) -> 2023 | I3: =E3*(1+'Formula Practice'!$B$3) -> 18299.4
A4: 2003 | B4: Mouse | C4: South | D4: Person 3 | E4: 23672 | F4: 44957 | G4: =TEXT(F4,"mmm") -> Jan | H4: =YEAR(F4) -> 2023 | I4: =E4*(1+'Formula Practice'!$B$3) -> 24855.6
A5: 2004 | B5: Printer | C5: East | D5: Person 4 | E5: 5264 | F5: 44972 | G5: =TEXT(F5,"mmm") -> Feb | H5: =YEAR(F5) -> 2023 | I5: =E5*(1+'Formula Practice'!$B$3) -> 5527.2
A6: 2005 | B6: Keyboard | C6: North | D6: Person 5 | E6: 43388 | F6: 44987 | G6: =TEXT(F6,"mmm") -> Mar | H6: =YEAR(F6) -> 2023 | I6: =E6*(1+'Formula Practice'!$B$3) -> 45557.4
A7: 2006 | B7: Mouse | C7: North | D7: Person 6 | E7: 19757 | F7: 45002 | G7: =TEXT(F7,"mmm") -> Mar | H7: =YEAR(F7) -> 2023 | I7: =E7*(1+'Formula Practice'!$B$3) -> 20744.85
A8: 2007 | B8: Mouse | C8: East | D8: Person 7 | E8: 32058 | F8: 45017 | G8: =TEXT(F8,"mmm") -> Apr | H8: =YEAR(F8) -> 2023 | I8: =E8*(1+'Formula Practice'!$B$3) -> 33660.9
A9: 2008 | B9: Keyboard | C9: East | D9: Person 8 | E9: 46429 | F9: 45032 | G9: =TEXT(F9,"mmm") -> Apr | H9: =YEAR(F9) -> 2023 | I9: =E9*(1+'Formula Practice'!$B$3) -> 48750.45
A10: 2009 | B10: Printer | C10: East | D10: Person 9 | E10: 19746 | F10: 45047 | G10: =TEXT(F10,"mmm") -> May | H10: =YEAR(F10) -> 2023 | I10: =E10*(1+'Formula Practice'!$B$3) -> 20733.3
A11: 2010 | B11: Keyboard | C11: South | D11: Person 10 | E11: 35185 | F11: 45062 | G11: =TEXT(F11,"mmm") -> May | H11: =YEAR(F11) -> 2023 | I11: =E11*(1+'Formula Practice'!$B$3) -> 36944.25
A12: 2011 | B12: Keyboard | C12: East | D12: Person 11 | E12: 33920 | F12: 45077 | G12: =TEXT(F12,"mmm") -> May | H12: =YEAR(F12) -> 2023 | I12: =E12*(1+'Formula Practice'!$B$3) -> 35616
A13: 2012 | B13: Monitor | C13: North | D13: Person 12 | E13: 35611 | F13: 45092 | G13: =TEXT(F13,"mmm") -> Jun | H13: =YEAR(F13) -> 2023 | I13: =E13*(1+'Formula Practice'!$B$3) -> 37391.55
... A21: 2020 | B21: Printer | C21: West | D21: Person 20 | E21: 33953 | F21: 45212 | G21: =TEXT(F21,"mmm") -> Oct | H21: =YEAR(F21) -> 2023 | I21: =E21*(1+'Formula Practice'!$B$3) -> 35650.65

Sheet Employee Data
A1: Employee ID | B1: Name | C1: Department | D1: Salary | E1: Joining Date | F1: Joining Year | G1: Years of Service | H1: Salary Category | I1: Name (Uppercase)
A2: 3001 | B2: Employee 1 | C2: Finance | D2: 86766 | E2: 42005 | F2: =YEAR(E2) -> 2015 | G2: =IF(E2>TODAY(),0,DATEDIF(E2,TODAY(),"Y")) -> 11 | H2: =IF(D2>=80000,"High","Standard") -> High | I2: =UPPER(B2) -> EMPLOYEE 1
A3: 3002 | B3: Employee 2 | C3: Finance | D3: 31943 | E3: 42255 | F3: =YEAR(E3) -> 2015 | G3: =IF(E3>TODAY(),0,DATEDIF(E3,TODAY(),"Y")) -> 11 | H3: =IF(D3>=80000,"High","Standard") -> Standard | I3: =UPPER(B3) -> EMPLOYEE 2
A4: 3003 | B4: Employee 3 | C4: HR | D4: 63374 | E4: 42505 | F4: =YEAR(E4) -> 2016 | G4: =IF(E4>TODAY(),0,DATEDIF(E4,TODAY(),"Y")) -> 10 | H4: =IF(D4>=80000,"High","Standard") -> Standard | I4: =UPPER(B4) -> EMPLOYEE 3
A5: 3004 | B5: Employee 4 | C5: Finance | D5: 109972 | E5: 42755 | F5: =YEAR(E5) -> 2017 | G5: =IF(E5>TODAY(),0,DATEDIF(E5,TODAY(),"Y")) -> 9 | H5: =IF(D5>=80000,"High","Standard") -> High | I5: =UPPER(B5) -> EMPLOYEE 4
A6: 3005 | B6: Employee 5 | C6: IT | D6: 54149 | E6: 43005 | F6: =YEAR(E6) -> 2017 | G6: =IF(E6>TODAY(),0,DATEDIF(E6,TODAY(),"Y")) -> 9 | H6: =IF(D6>=80000,"High","Standard") -> Standard | I6: =UPPER(B6) -> EMPLOYEE 5
A7: 3006 | B7: Employee 6 | C7: IT | D7: 78689 | E7: 43255 | F7: =YEAR(E7) -> 2018 | G7: =IF(E7>TODAY(),0,DATEDIF(E7,TODAY(),"Y")) -> 8 | H7: =IF(D7>=80000,"High","Standard") -> Standard | I7: =UPPER(B7) -> EMPLOYEE 6
A8: 3007 | B8: Employee 7 | C8: Marketing | D8: 35960 | E8: 43505 | F8: =YEAR(E8) -> 2019 | G8: =IF(E8>TODAY(),0,DATEDIF(E8,TODAY(),"Y")) -> 7 | H8: =IF(D8>=80000,"High","Standard") -> Standard | I8: =UPPER(B8) -> EMPLOYEE 7
A9: 3008 | B9: Employee 8 | C9: IT | D9: 91659 | E9: 43755 | F9: =YEAR(E9) -> 2019 | G9: =IF(E9>TODAY(),0,DATEDIF(E9,TODAY(),"Y")) -> 7 | H9: =IF(D9>=80000,"High","Standard") -> High | I9: =UPPER(B9) -> EMPLOYEE 8
A10: 3009 | B10: Employee 9 | C10: IT | D10: 90423 | E10: 44005 | F10: =YEAR(E10) -> 2020 | G10: =IF(E10>TODAY(),0,DATEDIF(E10,TODAY(),"Y")) -> 6 | H10: =IF(D10>=80000,"High","Standard") -> High | I10: =UPPER(B10) -> EMPLOYEE 9
A11: 3010 | B11: Employee 10 | C11: HR | D11: 107877 | E11: 44255 | F11: =YEAR(E11) -> 2021 | G11: =IF(E11>TODAY(),0,DATEDIF(E11,TODAY(),"Y")) -> 5 | H11: =IF(D11>=80000,"High","Standard") -> High | I11: =UPPER(B11) -> EMPLOYEE 10
A12: 3011 | B12: Employee 11 | C12: Finance | D12: 107634 | E12: 44505 | F12: =YEAR(E12) -> 2021 | G12: =IF(E12>TODAY(),0,DATEDIF(E12,TODAY(),"Y")) -> 4 | H12: =IF(D12>=80000,"High","Standard") -> High | I12: =UPPER(B12) -> EMPLOYEE 11
A13: 3012 | B13: Employee 12 | C13: Finance | D13: 35226 | E13: 44755 | F13: =YEAR(E13) -> 2022 | G13: =IF(E13>TODAY(),0,DATEDIF(E13,TODAY(),"Y")) -> 4 | H13: =IF(D13>=80000,"High","Standard") -> Standard | I13: =UPPER(B13) -> EMPLOYEE 12
... A21: 3020 | B21: Employee 20 | C21: Marketing | D21: 99924 | E21: 46755 | F21: =YEAR(E21) -> 2028 | G21: =IF(E21>TODAY(),0,DATEDIF(E21,TODAY(),"Y")) -> 0 | H21: =IF(D21>=80000,"High","Standard") -> High | I21: =UPPER(B21) -> EMPLOYEE 20

Sheet Formula Practice
A1: TASK HEADLING | B1: Value / Result | C1: Description | D1: Function | F1: FILTER: Average >80 | G1: Average | H1: Grade | I1: Student ID
A2: Passing marks | B2: 40 | C2: Editable threshold | D2: Absolute reference | F2: {=_xlfn._xlws.FILTER('Students Grade'!B2:B21,'Students Grade'!H2:H21>80,"No matches")} -> Student 12 | G2: {=_xlfn._xlws.FILTER('Students Grade'!H2:H21,'Students Grade'!H2:H21>80,"")} -> 84.333333 | H2: {=_xlfn._xlws.FILTER('Students Grade'!I2:I21,'Students Grade'!H2:H21>80,"")} -> A | I2: {=_xlfn._xlws.FILTER('Students Grade'!A2:A21,'Students Grade'!H2:H21>80,"")} -> 1012
A3: Sales bonus rate | B3: 0.05 | C3: Editable percentage | D3: Absolute reference | F3: Student 13 | G3: 95 | H3: A | I3: 1013
A5: Students scoring >60 in Math | B5: =COUNTIF('Students Grade'!C2:C21,">60") -> 19 | C5: Based on original screenshot data | D5: COUNTIF
A6: Students scoring >60 in all 3 | B6: =COUNTIFS('Students Grade'!C2:C21,">60",'Students Grade'!D2:D21,">60",'Students Grade'!E2:E21,">60") -> 6 | C6: Based on original screenshot data | D6: COUNTIFS
A7: Math & Science >50 | B7: =COUNTIFS('Students Grade'!C2:C21,">50",'Students Grade'!D2:D21,">50") -> 15 | C7: Based on original screenshot data | D7: COUNTIFS
A8: Average Math score | B8: =AVERAGE('Students Grade'!C2:C21) -> 80.2 | C8: Based on original screenshot data | D8: AVERAGE
A9: Math score for ID 1005 | B9: =INDEX('Students Grade'!C2:C21,MATCH(1005,'Students Grade'!A2:A21,0)) -> 68 | C9: Based on original screenshot data | D9: INDEX/MATCH
A10: Student 1003 full name | B10: =VLOOKUP(1003,'Students Grade'!A2:B21,2,FALSE) -> Student 3 | C10: Based on original screenshot data | D10: VLOOKUP
A11: Student 1005 English mark | B11: =_xlfn.XLOOKUP(1005,'Students Grade'!A2:A21,'Students Grade'!E2:E21,"Not found") -> 84 | C11: Based on original screenshot data | D11: XLOOKUP
A12: Position of student 1010 | B12: =_xlfn.XMATCH(1010,'Students Grade'!A2:A21,0) -> 10 | C12: Based on original screenshot data | D12: XMATCH
A13: Students with avg above 80 | B13: =COUNTIF('Students Grade'!H2:H21,">80") -> 2 | C13: Based on original screenshot data | D13: COUNTIF
A14: Total sales for Keyboard | B14: =SUMIF('Sales Data'!B2:B21,"Keyboard",'Sales Data'!E2:E21) -> 165970 | C14: Based on original screenshot data | D14: SUMIF
A15: Total East region sales | B15: =SUMIFS('Sales Data'!E2:E21,'Sales Data'!C2:C21,"East") -> 173932 | C15: Based on original screenshot data | D15: SUMIFS
A16: Average sales in East | B16: =AVERAGEIFS('Sales Data'!E2:E21,'Sales Data'!C2:C21,"East") -> 21741.5 | C16: Based on original screenshot data | D16: AVERAGEIFS | F16: FILTER: Sales >30000 | G16: Amount | H16: Region | I16: Sales ID
A17: Sales amount for ID 2005 | B17: =VLOOKUP(2005,'Sales Data'!A2:E21,5,FALSE) -> 43388 | C17: Based on original screenshot data | D17: VLOOKUP | F17: {=_xlfn._xlws.FILTER('Sales Data'!B2:B21,'Sales Data'!E2:E21>30000,"")} -> Keyboard | G17: {=_xlfn._xlws.FILTER('Sales Data'!E2:E21,'Sales Data'!E2:E21>30000,"")} -> 43388 | H17: {=_xlfn._xlws.FILTER('Sales Data'!C2:C21,'Sales Data'!E2:E21>30000,"")} -> North | I17: {=_xlfn._xlws.FILTER('Sales Data'!A2:A21,'Sales Data'!E2:E21>30000,"")} -> 2005
A18: Keyboard sales in East | B18: =SUMIFS('Sales Data'!E2:E21,'Sales Data'!B2:B21,"Keyboard",'Sales Data'!C2:C21,"East") -> 80349 | C18: Based on original screenshot data | D18: SUMIFS | F18: Mouse | G18: 32058 | H18: East | I18: 2007
A19: Price lookup: Keyboard sales | B19: =INDEX('Sales Data'!E2:E21,MATCH("Keyboard",'Sales Data'!B2:B21,0)) -> 7048 | C19: Based on original screenshot data | D19: INDEX/MATCH | F19: Keyboard | G19: 46429 | H19: East | I19: 2008
A20: Salary for employee 3008 | B20: =_xlfn.XLOOKUP(3008,'Employee Data'!A2:A21,'Employee Data'!D2:D21,"Not found") -> 91659 | C20: Based on original screenshot data | D20: XLOOKUP | F20: Keyboard | G20: 35185 | H20: South | I20: 2010
A21: HR employees | B21: =COUNTIF('Employee Data'!C2:C21,"HR") -> 6 | C21: Based on original screenshot data | D21: COUNTIF | F21: Keyboard | G21: 33920 | H21: East | I21: 2011
A22: Average Finance salary | B22: =AVERAGEIFS('Employee Data'!D2:D21,'Employee Data'!C2:C21,"Finance") -> 80952.333 | C22: Based on original screenshot data | D22: AVERAGEIFS | F22: Monitor | G22: 35611 | H22: North | I22: 2012
A23: Employee 3001 joining year | B23: =YEAR(INDEX('Employee Data'!E2:E21,MATCH(3001,'Employee Data'!A2:A21,0))) -> 2015 | C23: Based on original screenshot data | D23: YEAR/INDEX/MATCH | F23: Monitor | G23: 41871 | H23: North | I23: 2017
A24: Employee 3001 salary via INDIRECT | B24: =INDIRECT("'Employee Data'!D2") -> 86766 | C24: Based on original screenshot data | D24: INDIRECT | F24: Monitor | G24: 38161 | H24: West | I24: 2018
A25: Employee 3002 salary via OFFSET | B25: =OFFSET('Employee Data'!D2,1,0) -> 31943 | C25: Based on original screenshot data | D25: OFFSET | F25: Mouse | G25: 30436 | H25: West | I25: 2019
A26: Today | B26: =TODAY() -> 46323 | C26: Based on original screenshot data | D26: TODAY | F26: Printer | G26: 33953 | H26: West | I26: 2020
A27: Current year | B27: =YEAR(TODAY()) -> 2026 | C27: Based on original screenshot data | D27: YEAR
A28: Math rounded average | B28: =ROUND(AVERAGE('Students Grade'!C2:C21),2) -> 80.2 | C28: Based on original screenshot data | D28: ROUND
A29: Text extraction from Student 1 | B29: =LEFT('Students Grade'!B2,7) -> Student | C29: Based on original screenshot data | D29: LEFT
A30: Text length | B30: =LEN('Students Grade'!B2) -> 9 | C30: Based on original screenshot data | D30: LEN
A31: Student 1 formatted enrollment | B31: =TEXT('Students Grade'!F2,"dd-mmm-yyyy") -> 01-Jan-2018 | C31: Based on original screenshot data | D31: TEXT
A32: Students scoring >80 in Math | B32: =COUNTIF('Students Grade'!C2:C21,">80") -> 10 | C32: Based on original screenshot data | D32: COUNTIF | F32: Dynamic lookup Employee ID | G32: 3008 | H32: Salary
A33: Total sales | B33: =SUM('Sales Data'!E2:E21) -> 507725 | C33: Based on original screenshot data | D33: SUM | H33: =_xlfn.XLOOKUP(G32,'Employee Data'!A2:A21,'Employee Data'!D2:D21,"Not found") -> 91659
A34: Highest salary | B34: =MAX('Employee Data'!D2:D21) -> 116284 | C34: Based on original screenshot data | D34: MAX
A36: IF with absolute pass threshold | B36: =IF('Students Grade'!C2>=$B$2,"Pass","Fail") -> Pass | C36: Live formula from original dataset | D36: IF / absolute reference
A37: Nested IF grade | B37: =IF('Students Grade'!H2>=90,"A+",IF('Students Grade'!H2>=80,"A",IF('Students Grade'!H2>=60,"B","C"))) -> B | C37: Live formula from original dataset | D37: Nested IF
A38: IF AND both scores >80 | B38: =IF(AND('Students Grade'!C2>80,'Students Grade'!D2>80),"Yes","No") -> No | C38: Live formula from original dataset | D38: IF AND
A39: IF OR Math or English >80 | B39: =IF(OR('Students Grade'!C2>80,'Students Grade'!E2>80),"Yes","No") -> No | C39: Live formula from original dataset | D39: IF OR
A40: Dynamic employee salary ID 3005 | B40: =_xlfn.XLOOKUP(3005,'Employee Data'!A2:A21,'Employee Data'!D2:D21,"Not found") -> 54149 | C40: Live formula from original dataset | D40: XLOOKUP
A41: Dynamic employee row position | B41: =_xlfn.XMATCH(3005,'Employee Data'!A2:A21,0) -> 5 | C41: Live formula from original dataset | D41: XMATCH
A42: Employee salary INDEX MATCH | B42: =INDEX('Employee Data'!D2:D21,MATCH(3005,'Employee Data'!A2:A21,0)) -> 54149 | C42: Live formula from original dataset | D42: INDEX/MATCH
...

Sheet Product Price Lookup
A1: Product | B1: Unit Price | C1: Total Sales Amount | D1: Transactions | F1: Product lookup input | G1: Lookup result
A2: Keyboard | B2: 800 | C2: =SUMIF('Sales Data'!$B$2:$B$21,A2,'Sales Data'!$E$2:$E$21) -> 165970 | D2: =COUNTIF('Sales Data'!$B$2:$B$21,A2) -> 5 | F2: Keyboard | G2: =VLOOKUP(F2,$A$2:$B$6,2,FALSE) -> 800
A3: Printer | B3: 12000 | C3: =SUMIF('Sales Data'!$B$2:$B$21,A3,'Sales Data'!$E$2:$E$21) -> 76391 | D3: =COUNTIF('Sales Data'!$B$2:$B$21,A3) -> 4 | F3: printer | G3: =IFERROR(IF(VLOOKUP(F3,$A$2:$B$6,2,FALSE)="","Price not supplied",VLOOKUP(F3,$A$2:$B$6,2,FALSE)),"Product not found") -> 12000
A4: Mouse | B4: 500 | C4: =SUMIF('Sales Data'!$B$2:$B$21,A4,'Sales Data'!$E$2:$E$21) -> 111200 | D4: =COUNTIF('Sales Data'!$B$2:$B$21,A4) -> 5
A5: Monitor | B5: 15000 | C5: =SUMIF('Sales Data'!$B$2:$B$21,A5,'Sales Data'!$E$2:$E$21) -> 115643 | D5: =COUNTIF('Sales Data'!$B$2:$B$21,A5) -> 3
A6: Laptop | B6: 45000 | C6: =SUMIF('Sales Data'!$B$2:$B$21,A6,'Sales Data'!$E$2:$E$21) -> 38521 | D6: =COUNTIF('Sales Data'!$B$2:$B$21,A6) -> 3
